Workbook

Sheet Dashboard
B2: GABINETE DO VEREADOR FLÁVIO VALLE
B4: PAINEL | T4: ACERVO
C5: Data | E5: Agendas Realizadas | G5: Indicações Parl. Enviadas | I5: Medalhas 2025 | M5: Projetos Protocolados | O5: Total Imprensa | Q5: Base Contatos | U5: MATERIAL GRÁFICO | W5: APRESENTAÇÕES | Y5: PROJETOS | AA5: LEIS SANCIONADAS | AC5: ESTUDOS
C6: =TODAY() -> 46083 | E6: =counta(Agendas!A:A) -> 1883 | G6: =COUNTA('Indicações'!C:C) -> 659 | J6: Pedro Ernesto | K6: 45780 | M6: =COUNTA('Proposições legislativas'!B3:B1017) -> 63 | O6: =counta('Assessoria de Imprensa'!A:A) -> 292 | Q6: 18308 | U6: PLACA CARDOSÃO | W6: ='Apresentações'!G2 -> RIO EM ORDEM | Y6: PROJETO VAGA VIVA | AA6: LEI CORRIDA VERA CRUZ | AC6: Custo do antissemitismo
J7: Chiquinha Gonzaga | K7: 45718 | U7: ESTATUTO DA ORLA | W7: ='Apresentações'!G3 -> PLANEJAMENTO COMUNICAÇÃO | Y7: PROJETO CARDOSÃO NATUREZA IMATERIAL | AA7: LEI COMPLEMENTAR INTERVENÇÃO RISCO ESTRUTURAL | AC7: Relevância da educação para economia
J8: São Francisco | K8: 45780 | U8: FEST RIO | W8: ='Apresentações'!G4 -> DECK RIO | Y8: PROJETO CARDOSÃO INTERESSE CULTURAL | AA8: LEI PADARIA IPANEMA | AC8: Nota sobre regulamentação do Airbnb
C9: Dias de mandato | E9: Gab. Itinerante | G9: Moções Entregues | J9: Título de Cidadão | K9: 45718 | M9: Leis Sancionadas | O9: Posts Instagram | Q9: Atendimentos | U9: ORLA ORDENADA | W9: ='Apresentações'!G5 -> ISS CONSERVAÇÃO | Y9: PROJETO CIRCUITO CARIOCA INTERESSE CULTURAL | AA9: LEI DIA DO COMBATE AO ANTISSEMITISMO | AC9: Impacto da implementação do BRT
C10: =DAYS(C6,"01/01/2025") -> 425 | E10: =COUNTIF('Gabinete Itinerante'!E:E,'Gabinete Itinerante'!E2) -> 16 | G10: =counta('Moções'!A:A) -> 403 | J10: Título Esportivo | K10: 45658 | M10: =COUNTIF('Proposições legislativas'!B:B,'Tabelas e Gráficos'!A21) -> 17 | O10: =COUNTA('Comunicação Digital'!E:E) -> 368 | Q10: 1503 | U10: ADESIVO GABINETE | W10: ='Apresentações'!G6 -> TURISMO - VISIT RIO | Y10: PROJETO CIRCUITO CARIOCA NATUREZA IMATERIAL | AA10: LEI CARDOSÃO NATUREZA IMATERIAL | AC10: Impacto econômico do turismo no Rio de Janeiro
U11: ADESIVOS ORLA | W11: ='Apresentações'!G7 -> 100 DIAS DE MANDATO | Y11: PROJETO DEFINIÇÃO ANTISSEMITISMO | AA11: LEI CARDOSÃO INTERESSE CULTURAL | AC11: Panorama dos acidentes de trânsito
U12: ADESIVOS AIRBNB | W12: ='Apresentações'!G8 -> AUDIÊNCIA PÚBLICA: REGULAMENTAÇÃO DO SERVIÇO DE LOCAÇÃO POR TEMPORADA | Y12: PROJETO SAMBANTERO CALENDÁRIO DA CIDADE | AA12: LEI SISTEMA DE ÁREA AZUL DIGITAL | AC12: Segurança Presente
U13: BALCÃO STAND | W13: ='Apresentações'!G9 -> REVIVA ORLA | Y13: PROJETO SAMBANTERO NATUREZA IMATERIAL | AA13: LEI CIRCUITO CARIOCA NATUREZA IMATERIAL | AC13: Cassinos e jogos de azar
B14: INDICADORES | U14: CADERNETA LIDERA | W14: ='Apresentações'!G10 -> TURISMO - CONSELHO DA ORLA | Y14: PROJETO DIA DO COMBATE AO ANTISSEMITISMO | AA14: LEI SAMBANTERO CALENDÁRIO DA CIDADE | AC14: Corridas de rua
C15: AGENDAS | U15: ROTEIRO HISTÓRICO CULTURAL JUDAICO | W15: ='Apresentações'!G11 -> RIO: CAPITAL DO TURISMO NO BRASIL | Y15: PROJETO CAMPANHA MUNICIPAL PARA PROMOÇÃO DE ESTACIONAMENTO REGULAR | AA15: LEI DIA DA AMIZADE BRASIL-ISRAEL NO CALENDÁRIO | AC15: Custo econômico da violência
U16: COLETE | W16: ='Apresentações'!G12 -> LIDERA RIO | O PAPEL DO LEGISLATIVO NA CONSTRUÇÃO DO ORÇAMENTO PÚBLICO | Y16: PROJETO DECK RIO | AA16: LEI NOME DO ANDRÉ DO VALLE A UNIDADE DE ENSINO | AC16: Megaeventos esportivos
U17: CORDÃO VERSO | W17: ='Apresentações'!G13 -> A IMPORTÂNCIA DOS JUDEUS NA POLÍTICA CARIOCA | Y17: PROJETO ISS CONSERVAÇÃO | AA17: LEI COMLURB PATRIMÔNIO CULTURAL | AC17: Turismo e capitalidade
U18: CORDÃO FRENTE | W18: ='Apresentações'!G14 -> AUDIÊNCIA PÚBLICA: O RIO E SUAS ORLAS UM PATRIMÔNIO EM DISCUSSÃO | Y18: PROJETO TÍTULO DE CIDADÃO HONORÁRIO PAULO HENRIQUE GANSO | AA18: LEI NOME DE MARIANGELES IBARRA MAIA A LOGRADOURO OU EQUIPAMENTO PÚBLICO | AC18: Conselhos fiscais
U19: DOBRA CARTEIRA | W19: ='Apresentações'!G15 -> LIDERA RIO | Y19: PROJETO TÍTULO DE CIDADÃO HONORÁRIO EDUARDO MANEIRA | AA19: LEI CIDADE SAN SEBASTIAN COMO CIDADE-IRMÃ | AC19: Motivos para aprovar o empréstimo
U20: FLYER MANDATO PARTICIPATIVO | W20: ='Apresentações'!G16 -> AQUI TEM CEP | Y20: PROJETO SERVIÇOS DE ENTREGA | AA20: LEI DIA DE IEMANJÁ DO ARPOADOR | AC20: Orçamento 2024 (LDO 2026)
U21: ILUSTRADOR CANETA PLÁSTICA | W21: ='Apresentações'!G17 -> LIDERA RIO | Y21: PROJETO POLUIÇÃO SONORA | AA21: LEI DIA DE IEMANJÁ DO ARPOADOR NO CALENDÁRIO | AC21: VLT/BRT
U22: MATEIROS ADESIVOS | W22: ='Apresentações'!G18 -> ORLA QUE QUEREMOS | Y22: PROJETO COMERCIALIZAÇÃO DE ANIMAIS | AA22: LEI VEREADOR JUVENIL
U23: ROTEIRO HISTÓRICO CULTURAL JUDAICO | W23: ='Apresentações'!G19 -> WORKSHOP DE MOBILIZAÇÃO & COMUNICAÇÃO POLÍTICA | Y23: PROJETO CONSELHO FISCAL INDEPENDENTE
U24: PIRULITO FRENTE | W24: ='Apresentações'!G20 -> JUNTOS RENOVANDO O RIO: UM MANDATO COLETIVO | Y24: PROJETO TOMBAMENTO IMÓVEL FLAMENGO
U25: PIRULITO VERSO | W25: ='Apresentações'!G21 -> DINÂMICA DE ELABORAÇÃO DE PROJETO DE LEI MUNICIPAL | Y25: PROJETO MIRANTE DO PEDRÃO
U26: REVISTA A5 | W26: ='Apresentações'!G22 -> PROJETO ESTATUTO DA ORLA | Y26: PROJETO SELO DE RELEVÂNCIA TURÍSTICA
U27: REVISTA A5 SEIS MESES | W27: ='Apresentações'!G23 | Y27: PROJETO ESTATUTO DA ORLA
U28: SEU VEREADOR CARTÃO | W28: ='Apresentações'!G24 | Y28: PROJETO MUNICIPALIZAÇÃO FLORESTA DA TIJUCA
U29: WINDBANNER | W29: ='Apresentações'!G25 | Y29: PROJETO NATURALIZAÇÃO DA LAGOA (PARQUE DOS PATINS)
C30: PRODUÇÃO LEGISLATIVA | W30: ='Apresentações'!G26 | Y30: PROJETO NATURALIZAÇÃO LAGOA (PARQUE CANTAGALO)
W31: ='Apresentações'!G27 | Y31: PROJETO ARNALDO QUINTELA INTERESSE TURÍSTICO
W32: ='Apresentações'!G28 | Y32: PROJETO BAIXO LAGOA
W33: ='Apresentações'!G29 | Y33: PROJETO VENDAS E LOCAÇÕES BIKE ELÉTRICA
W34: ='Apresentações'!G30 | Y34: PROJETO PROGRAMA ADOÇÃO CARIOCA
W35: ='Apresentações'!G31 | Y35: PROJETO RIO CELEBRA
W36: ='Apresentações'!G32 | Y36: PROJETO CRISTO REDENTOR
W37: ='Apresentações'!G33 | Y37: PROJETO ENTREGA DE PRODUTOS NA ORLA
W38: ='Apresentações'!G34 | Y38: PROJETO TÍTULO DE CIDADÃO HONORÁRIO ILAN GOLDFAJN
W39: ='Apresentações'!G35 | Y39: PROJETO ARNALDO QUINTELA (HORÁRIO DE FUNCIONAMENTO)
W40: ='Apresentações'!G36 | Y40: PROJETO ROTEIRO TURÍSTICO JUDAICO
W41: ='Apresentações'!G37 | Y41: PROJETO FINANÇAS IDOSOS
W42: ='Apresentações'!G38 | Y42: PROJETO ENSINO SOBRE O HOLOCAUSTO
...

Sheet Agendas
A1: Título | B1: Descrição | C1: Local | D1: Começo | E1: Convidados | F1: Mês | H1: Classificação
A2: Pré matrícula mestrado FGV | D2: 45644 | F2: =TEXT(D2, "mm/yyyy") -> 12/2024 | H2: Mestrado
A3: Posse do Prefeito, Vice-prefeito e Vereadores | B3: *Amigo e amiga*, *O convite da POSSE do Prefeito, Vice-prefeito e Vereadores, marcada para o dia 01 de janeiro/2025, às 09h30min, no Plenário Teotônio Villela, com as devidas orientações e as 4 pulseiras para os convidados terem acesso à galeria e ainda as 3 pulseiras para os convidados terem acesso ao Salão Nobre, já estão à disposição na Presidência.* Verinha à disposição | C3: Câmara Municipal do Rio de Janeiro, Praça Floriano - Centro, Rio de Janeiro - RJ, 20031-050, Brasil | D3: 45658.396 | E3: flaviogvalle@gmail.com | F3: =TEXT(D3, "mm/yyyy") -> 01/2025 | H3: Eventos
A4: Reunião - Organização GVFV | C4: Câmara Municipal do Rio de Janeiro, Praça Floriano - Centro, Rio de Janeiro - RJ, 20031-050, Brasil | D4: 45659.438 | E4: lucasrosa.arq@gmail.com;lfdsbr@gmail.com | F4: =TEXT(D4, "mm/yyyy") -> 01/2025 | H4: Reunião Interna/Planejamento
A5: Reunião Política | C5: Câmara Municipal do Rio de Janeiro, Praça Floriano - Centro, Rio de Janeiro - RJ, 20031-050, Brasil | D5: 45659.542 | E5: lucasrosa.arq@gmail.com;flaviogvalle@gmail.com;leomartins.rzs@gmail.com;monteirojpf@gmail.com;gisellygazevedo@gmail.com;lfdsbr@gmail.com | F5: =TEXT(D5, "mm/yyyy") -> 01/2025 | H5: Reunião Interna/Planejamento
A6: Treinamento Wrike | B6: Informações Evento Data: 02/01 Horário: 14:30h Local: Gabinete 506 Observações: Treinamento Plataforma Wrike Responsável: Solicitado p/ FV em 29/12 | C6: Câmara Municipal do Rio de Janeiro, Praça Floriano - Centro, Rio de Janeiro - RJ, 20031-050, Brasil | D6: 45659.604 | E6: lucasrosa.arq@gmail.com;otaviobopp@gmail.com;leonardosolabloise@gmail.com;lauranalbq@gmail.com;viniciusmmg@gmail.com;juliagardel2@gmail.com;pedroangelito22@gmail.com;contato.lucasfajardo@gmail.com;flaviogvalle@gmail.com;andrew.mata.2022@gmail.com;leomartins.rzs@gmail.com;monteirojpf@gmail.com;crislobo@gmail.com;lfdsbr@gmail.com;lima.saramoreira@gmail.com;biarsbz@gmail.com;rafaazamor@gmail.com;matheus.ocn@gmail.com;gisellygazevedo@gmail.com;martinsmt1000@gmail.com | F6: =TEXT(D6, "mm/yyyy") -> 01/2025 | H6: Reunião Interna/Planejamento
A7: Reunião - Marcel Balassiano | B7: Informado p/ Léo Fernandes em 01/01. | C7: Câmara Municipal do Rio de Janeiro, Praça Floriano - Centro, Rio de Janeiro - RJ, 20031-050, Brasil | D7: 45659.688 | E7: flaviogvalle@gmail.com;lfdsbr@gmail.com;marcel.balassiano@fgv.br | F7: =TEXT(D7, "mm/yyyy") -> 01/2025 | H7: Reunião Executivo
A8: Reunião - Luiz Murillo Tobias | B8: Informado p/ Leo Fernandes em 02/01 | C8: Câmara Municipal do Rio de Janeiro, Praça Floriano - Centro, Rio de Janeiro - RJ, 20031-050, Brasil | D8: 45660.458 | E8: flaviogvalle@gmail.com;lfdsbr@gmail.com | F8: =TEXT(D8, "mm/yyyy") -> 01/2025 | H8: Reunião Executivo
A9: Reunião - Bruno Ramos | B9: Informações Evento Data: 03/01 Horário: 10h Local: Gabinete 506 Observações: Solicitado p/ FV em 02/01 | C9: Câmara Municipal do Rio de Janeiro, Praça Floriano - Centro, Rio de Janeiro - RJ, 20031-050, Brasil | D9: 45660.542 | E9: flaviogvalle@gmail.com;brfbruno2@gmail.com | F9: =TEXT(D9, "mm/yyyy") -> 01/2025 | H9: Reunião Executivo
A10: Entrevista Estagiário - Jiskya | D10: 45663.604 | E10: torresjiskya@gmail.com;flaviogvalle@gmail.com | F10: =TEXT(D10, "mm/yyyy") -> 01/2025 | H10: Reunião Interna/Planejamento
A11: Entrevista Estagiário - Kelvin | D11: 45663.625 | E11: kelvinmafra1@gmail.com;flaviogvalle@gmail.com | F11: =TEXT(D11, "mm/yyyy") -> 01/2025 | H11: Reunião Interna/Planejamento
A12: Entrevista Estagiário - Renato | D12: 45663.646 | E12: leonardo.moog@hotmail.com;flaviogvalle@gmail.com;renato-908070@hotmail.com | F12: =TEXT(D12, "mm/yyyy") -> 01/2025 | H12: Reunião Interna/Planejamento
A13: Reunião - Sec. Lucas Padilha | B13: *MARCADO* Reunião com vereador Flavio Valle, segunda-feira, 6 de jan. · 17:30 Câmara Municipal do Rio de Janeiro, Praça Floriano | C13: Câmara Municipal do Rio de Janeiro, Praça Floriano - Centro, Rio de Janeiro - RJ, 20031-050, Brasil | D13: 45663.729 | E13: ce.lopess57@gmail.com;flaviogvalle@gmail.com | F13: =TEXT(D13, "mm/yyyy") -> 01/2025 | H13: Reunião Executivo
A14: Entrevista Estagiário - Lucas Vidal | D14: 45664.583 | E14: lucasfvida@gmail.com;leonardo.moog@hotmail.com;flaviogvalle@gmail.com | F14: =TEXT(D14, "mm/yyyy") -> 01/2025 | H14: Reunião Interna/Planejamento
A15: Reunião Diego Vaz + Vereador Flávio Valle | B15: Agendado: Reunião Diego Vaz + Vereador Flávio Valle Quarta-feira, 07 de Janeiro de 2025. 18h Local: Secretaria de Conservação (Rua Maia Lacerda, 167- Estácio - 5° andar) | C15: R. Maia de Lacerda, 167 - Estácio, Rio de Janeiro - RJ, 20250-001, Brasil | D15: 45664.75 | E15: flaviogvalle@gmail.com | F15: =TEXT(D15, "mm/yyyy") -> 01/2025 | H15: Reunião Executivo
A16: Reunião Jockey e IRPH | B16: Informações Evento Data: 08/01 Horário: 11:30H Local: Rua Gago Coutinho, n° 52 3º andar - Laranjeiras Observações: Boa Tarde Lucas! A reunião será no dia 08/01(4ªfeira) às 11h no IRPH (Rua Gago Coutinho, n° 52 3º andar - Laranjeiras.) Att, Ariele Contato: Enviado p/ FV em 23/12 | C16: R. Gago Coutinho, 52 - Laranjeiras, Rio de Janeiro - RJ, 22221-070, Brasil | D16: 45665.479 | E16: flaviogvalle@gmail.com | F16: =TEXT(D16, "mm/yyyy") -> 01/2025 | H16: Reunião Executivo
A17: Reunião - Edmilson (Educação) | B17: Informações Evento Data: 08/01 Horário: 13:30h Local: Câmara Municipal do Rio de Janeiro - Gabinete 506 Observações: Pauta relacionada a continuidade do trabalho na Educação Contato: +55 21 98155-6601 | C17: Câmara Municipal do Rio de Janeiro, Praça Floriano - Centro, Rio de Janeiro - RJ, 20031-050, Brasil | D17: 45665.562 | E17: flaviogvalle@gmail.com | F17: =TEXT(D17, "mm/yyyy") -> 01/2025 | H17: Reunião Executivo
A18: Jantar - Edu Goldenberg + Joyce Trindade + Lucas Padilha | B18: Informações Evento Data: 08/01 Horário: 20h Local: Casa do Edu Goldenberg Rua Domingos Ferreira 178, apto. 702. Observações: Levar vinho Responsável: Léo Fernandes | C18: R. Domingos Ferreira, 178 - apto 702 - Copacabana, Rio de Janeiro - RJ, 22050-012, Brasil | D18: 45665.833 | E18: flaviogvalle@gmail.com;lfdsbr@gmail.com | F18: =TEXT(D18, "mm/yyyy") -> 01/2025 | H18: Compromissos Pessoais FV
A19: Reunião - Otávio Leite | B19: Informações Evento Data: 09/01 Horário: 09:30h Local: Marquês de Abrantes, 99/10º Andar. Observações: Agenda/bate-papo sobre turismo. Responsável: Léo Fernandes | C19: R. Marquês de Abrantes, 99 - Flamengo, Rio de Janeiro - RJ, 22230-061, Brasil | D19: 45666.396 | E19: flaviogvalle@gmail.com;lfdsbr@gmail.com | F19: =TEXT(D19, "mm/yyyy") -> 01/2025 | H19: Reunião Atendimento
A20: Reunião com Dr Carlos Ivan e Dr Sérgio Werlang | B20: Reunião com Dr Carlos Ivan e Dr Sérgio Werlang Data : 09/01/2025 Horário : 11h30 Local : FGV sede Praia de Botafogo, 190 - Botafogo - 12° andar | C20: Fundação Getulio Vargas, Praia de Botafogo, 190 - Botafogo, Rio de Janeiro - RJ, 22250-145, Brasil | D20: 45666.479 | E20: flaviogvalle@gmail.com | F20: =TEXT(D20, "mm/yyyy") -> 01/2025 | H20: Reunião Atendimento
A21: Reunião - Fabinho | B21: Informações Evento Data: 09/01 Horário: 16:30h Local: Gabinete 506 Observações: Solicitado p/ Fabinho para tratar de assuntos pessoais. | C21: Câmara Municipal do Rio de Janeiro, Praça Floriano - Centro, Rio de Janeiro - RJ, 20031-050, Brasil | D21: 45666.625 | E21: fabiocampellobjj@gmail.com;flaviogvalle@gmail.com | F21: =TEXT(D21, "mm/yyyy") -> 01/2025 | H21: Reunião Interna/Planejamento
A22: Reunião - Ana Ribeiro | B22: Informações Evento Data: 09/01 Horário: 15:30h Local: Câmara Municipal do Rio de Janeiro, Praça Floriano - Centro Contato: Solicitado p/ João | C22: Câmara Municipal do Rio de Janeiro, Praça Floriano - Centro, Rio de Janeiro - RJ, 20031-050, Brasil | D22: 45666.646 | E22: viniciusmmg@gmail.com;flaviogvalle@gmail.com;leomartins.rzs@gmail.com;monteirojpf@gmail.com | F22: =TEXT(D22, "mm/yyyy") -> 01/2025 | H22: Reunião Interna/Planejamento
A23: Reunião - Rafael Azamor | C23: Câmara Municipal do Rio de Janeiro, Praça Floriano - Centro, Rio de Janeiro - RJ, 20031-050, Brasil | D23: 45666.708 | E23: rafaazamor@gmail.com;flaviogvalle@gmail.com | F23: =TEXT(D23, "mm/yyyy") -> 01/2025 | H23: Reunião Interna/Planejamento
A24: Evento: Happy Hour Maravalley | B24: Informações Evento Data: 09/01 Horário: 17h Local: Porto Maravalley, Av. Prof. Pereira Reis, 76 Observações: Gente, o Marcel Balassiano, subsecretário de desenvolvimento econômico e inovação da Prefeitura, pediu para eu repassar esse convite a vocês, para quem tiver interesse em comparecer amanhã. Contato: Responsável: Leonardo Moog | C24: Porto Maravalley, Av. Prof. Pereira Reis, 76 - Santo Cristo, Rio de Janeiro - RJ, 20220-800, Brasil | D24: 45666.75 | E24: leonardo.moog@hotmail.com;flaviogvalle@gmail.com;lfdsbr@gmail.com | F24: =TEXT(D24, "mm/yyyy") -> 01/2025 | H24: Eventos
A25: Jantar | D25: 45666.854 | E25: flaviogvalle@gmail.com | F25: =TEXT(D25, "mm/yyyy") -> 01/2025 | H25: Compromissos Pessoais FV
A26: Gravação Vídeo Chuvas | C26: R. Mena Barreto, 129 - Botafogo, Rio de Janeiro - RJ, 22271-100, Brasil | D26: 45667.396 | E26: contato.lucasfajardo@gmail.com;flaviogvalle@gmail.com;gisellygazevedo@gmail.com | F26: =TEXT(D26, "mm/yyyy") -> 01/2025 | H26: Comunicação/Imprensa
A27: Café - Flavio + Andrew | D27: 45667.458 | E27: flaviogvalle@gmail.com | F27: =TEXT(D27, "mm/yyyy") -> 01/2025 | H27: Reunião Interna/Planejamento
A28: Gravação Vídeo Chuvas | C28: diversos locais | D28: 45667.5 | E28: contato.lucasfajardo@gmail.com;flaviogvalle@gmail.com;gisellygazevedo@gmail.com | F28: =TEXT(D28, "mm/yyyy") -> 01/2025 | H28: Comunicação/Imprensa
A29: Cláudio | C29: Confeitaria Kurt - Doces e Tortas, R. Gen. Urquiza, 117 B - Leblon, Rio de Janeiro - RJ, 22431-040, Brasil | D29: 45667.583 | F29: =TEXT(D29, "mm/yyyy") -> 01/2025 | H29: Reunião Atendimento
A30: Visita ao Hospital Oftalmológico com Almyr Sabrosa | B30: Informações Evento Data: 10/01 Horário: 14:30h Local: Rio Vision - Hospital oftalmológico, R. Prudente de Morais, 1276 Observações: Ida ao hospital oftalmológico com Almyr Sabrosa, para agradecimento e conhecer. Responsável: Bruno Ramos | C30: Rio Vision - Hospital oftalmológico, R. Prudente de Morais, 1276 - Ipanema, Rio de Janeiro - RJ, 22420-042, Brasil | D30: 45667.604 | E30: flaviogvalle@gmail.com;mrpaulobarros@gmail.com;brfbruno2@gmail.com | F30: =TEXT(D30, "mm/yyyy") -> 01/2025 | H30: Externa/Rua
A31: Celebração da Posse da Nova Diretoria da ARI | B31: Informações Evento Data: 10/01 Horário: A partir das 18h Melhor horário: 18:30h Local: R. Gen. Severiano, 170 - Botafogo Observações: A associação Religiosa Israelita - ARI tem a honra de convidas V.Sa. para a Celebração da Posse da Nova Diretoria e do Conselho Diretor para o Biênio 2025/26, no dia 10 de janeiro próximo, a partir das 18h, quando serão comemorados também os 83 anos de fundação da instituição com um Kabalat Shabat especial, seguido de um Lechaim comunitário no Salão Nobre. Contamos com sua presença para juntos celebrarmos mais este marco em nossa trajetória. Para confirmar sua presença, por favor, entre em contato por e-mail: meireles@aririo.org.br, ou telefones (21) 97650-9039; (21) 97641-6234; (21) 2156-0444, até as 12h de sexta-feira, 10 de janeiro. Contato: Recebido do Gabinete do Prefeito em 07/01 Responsável: Rafael Azamor | C31: R. Gen. Severiano, 170 - Botafogo, Rio de Janeiro - RJ, 22290-040, Brasil | D31: 45667.771 | E31: rafaazamor@gmail.com;flaviogvalle@gmail.com;lfdsbr@gmail.com | F31: =TEXT(D31, "mm/yyyy") -> 01/2025 | H31: Comunidade Judaica
A32: Conversa com a Associação de Moradores da Chácara do Céu | C32: Estr. do Vidigal, 555 - Vidigal, Rio de Janeiro - RJ, 22450-230, Brasil | D32: 45668.417 | E32: lucasjb27@hotmail.com;bernardorubiao@gmail.com;marcosbarato177@gmail.com;gabrielleal1995@gmail.com;joycenani.rio@gmail.com;leonardolopes@llfilm.com.br;flaviogvalle@gmail.com;leomartins.rzs@gmail.com;monteirojpf@gmail.com;mrpaulobarros@gmail.com;subzonasul.imprensa@gmail.com | F32: =TEXT(D32, "mm/yyyy") -> 01/2025 | H32: Externa/Rua
A33: Visita Terreirão do samba c/ associação dos barraqueiros | B33: Visita Terreirão do samba c/ associação dos barraqueiros - Chegada do Vereador Flavio Vale (Resp. agenda Marcelinho Doper) Sábado, 11 de janeiro⋅12:30 até 13:30 Terreirão do Samba Nelson Sargento R. Benedito Hipólito, 66 - Centro, Rio de Janeiro | C33: Terreirão do Samba Nelson Sargento, R. Benedito Hipólito, 66 - Centro, Rio de Janeiro - RJ, 20211-130, Brasil | D33: 45668.521 | E33: flaviogvalle@gmail.com | F33: =TEXT(D33, "mm/yyyy") -> 01/2025 | H33: Externa/Rua
A34: Descoberta da Matzeiva - Bernardo Griner | B34: Informações Evento Data: 12/01 Horário: 11h Local: Cemitério Israelita de Belford Roxo (Chevra Kadisha), Av. Automóvel Clube, 1921 - Jardim Gláucia, Belford Roxo Contato: Recebido p/ FV em 10/01 | C34: Cemitério Israelita de Belford Roxo (Chevra Kadisha), Av. Automóvel Clube, 1921 - Jardim Gláucia, Belford Roxo - RJ, 26196-030, Brasil | D34: 45669.458 | E34: rafaazamor@gmail.com;flaviogvalle@gmail.com | F34: =TEXT(D34, "mm/yyyy") -> 01/2025 | H34: Comunidade Judaica
A35: Reunião Márcio Ribeiro | D35: 45670.375 | F35: =TEXT(D35, "mm/yyyy") -> 01/2025 | H35: Reunião Legislativo
A36: Reunião Semanal - Comunicação e Imprensa | C36: Câmara Municipal do Rio de Janeiro, Praça Floriano - Centro, Rio de Janeiro - RJ, 20031-050, Brasil | D36: 45670.417 | E36: contato.lucasfajardo@gmail.com;flaviogvalle@gmail.com;monteirojpf@gmail.com;crislobo@gmail.com;gisellygazevedo@gmail.com;lfdsbr@gmail.com | F36: =TEXT(D36, "mm/yyyy") -> 01/2025 | H36: Reunião Interna/Planejamento
A37: Reunião Semanal - Pesquisa e Redação | C37: Câmara Municipal do Rio de Janeiro, Praça Floriano - Centro, Rio de Janeiro - RJ, 20031-050, Brasil | D37: 45670.438 | E37: lima.saramoreira@gmail.com;leonardo.moog@hotmail.com;pedroangelito22@gmail.com;flaviogvalle@gmail.com;monteirojpf@gmail.com;lfdsbr@gmail.com | F37: =TEXT(D37, "mm/yyyy") -> 01/2025 | H37: Reunião Interna/Planejamento
A38: Reunião Semanal - Atendimento | C38: Câmara Municipal do Rio de Janeiro, Praça Floriano - Centro, Rio de Janeiro - RJ, 20031-050, Brasil | D38: 45670.458 | E38: lauranalbq@gmail.com;flaviogvalle@gmail.com;andrew.mata.2022@gmail.com;monteirojpf@gmail.com;lfdsbr@gmail.com | F38: =TEXT(D38, "mm/yyyy") -> 01/2025 | H38: Reunião Interna/Planejamento
A39: Reunião Semanal - Gabinete | C39: Câmara Municipal do Rio de Janeiro, Praça Floriano - Centro, Rio de Janeiro - RJ, 20031-050, Brasil | D39: 45670.479 | E39: lucasrosa.arq@gmail.com;flaviogvalle@gmail.com;monteirojpf@gmail.com;lfdsbr@gmail.com | F39: =TEXT(D39, "mm/yyyy") -> 01/2025 | H39: Reunião Interna/Planejamento
A40: Fotos Equipe GVFV | B40: Comunicação irá fazer fotos individuais da equipe no gabinete. | C40: Câmara Municipal do Rio de Janeiro, Praça Floriano - Centro, Rio de Janeiro - RJ, 20031-050, Brasil | D40: 45670.562 | E40: otaviobopp@gmail.com;lucasrosa.arq@gmail.com;leonardosolabloise@gmail.com;leonardo.moog@hotmail.com;lauranalbq@gmail.com;viniciusmmg@gmail.com;juliagardel2@gmail.com;pedroangelito22@gmail.com;leonardolopes@llfilm.com.br;contato.lucasfajardo@gmail.com;leomartins.rzs@gmail.com;andrew.mata.2022@gmail.com;monteirojpf@gmail.com;crislobo@gmail.com;lfdsbr@gmail.com;lima.saramoreira@gmail.com;biarsbz@gmail.com;rafaazamor@gmail.com;matheus.ocn@gmail.com;mrpaulobarros@gmail.com;gisellygazevedo@gmail.com;martinsmt1000@gmail.com | F40: =TEXT(D40, "mm/yyyy") -> 01/2025 | H40: Comunicação/Imprensa
...

Sheet Gabinete Itinerante
A1: Edição | B1: Data | C1: Local | D1: Bairro | E1: Coluna 1
A2: 1 | B2: 45786 | C2: Praça Nelson Mandela | D2: Botafogo | E2: Concluído
A3: 2 | B3: 45787 | C3: Praça Tião Belo | D3: Botafogo | E3: Concluído
A4: 3 | B4: 45793 | C4: Metrô São Conrado | D4: Rocinha | E4: Concluído
A5: 4 | B5: 45800 | C5: Praça Sezerdelo | D5: Copacabana | E5: Concluído
A6: 5 | B6: 45807 | C6: Praça do Vidigal | D6: Vidigal | E6: Concluído
A7: 6 | B7: 45814 | C7: Largo dos Leões | D7: Humaitá | E7: Concluído
A8: 7 | B8: 45821 | C8: Ladeira dos Tabajaras | D8: Tabajaras | E8: Concluído
A9: 8 | B9: 45828 | C9: Feriado | D9: - | E9: Cancelado
A10: 9 | B10: 45835 | C10: Nossa Senhora da Paz | D10: Ipanema | E10: Concluído
A11: 10 | B11: 45842 | C11: Feriado | D11: - | E11: Cancelado
A12: 11 | B12: 45849 | C12: Praça Edmundo Bittencourt | D12: Copacabana | E12: Concluído
A13: 12 | B13: 45856 | C13: PPG | D13: Copacabana | E13: Concluído
... A24: 23 | B24: 45935 | C24: Praça Nossa Senhora da Paz | D24: Ipanema | E24: Concluído

Sheet Indicações
A1: - | B1: ÓRGÃO COMPETENTE | C1: RESUMO SOLICITAÇÃO | D1: DATA | E1: BAIRRO
A2: 1 | B2: COMLURB | C2: SOLICITA PROVIDÊNCIAS JUNTO À COMPANHIA MUNICIPAL DE LIMPEZA URBANA - COMLURB, VISANDO MANUTENÇÃO DE BRINQUEDOS DA PRAÇA ALMIRANTE JÚLIO DE NORONHA, BAIRRO DO LEME. | E2: LEME
A3: 2 | B3: COMLURB | C3: SOLICITA PROVIDÊNCIAS JUNTO À COMPANHIA MUNICIPAL DE LIMPEZA URBANA - COMLURB, VISANDO A LIMPEZA DO AMBULATÓRIO DA PRAIA DO PINTO, NO BAIRRO DO JARDIM BOTÂNICO | E3: JARDIM BOTÂNICO
A4: 3 | B4: CET-RIO | C4: SOLICITA PROVIDÊNCIAS JUNTO À COMPANHIA DE ENGENHARIA DE TRÁFEGO DO RIO DE JANEIRO - CET-RIO, VISANDO MANUTENÇÃO DA FAIXA DE PEDESTRES DA RUA PAULO BARRETO, 65, NO BAIRRO DE BOTAFOGO. | E4: BOTAFOGO
A5: 4 | B5: SMS | C5: SOLICITA PROVIDÊNCIAS JUNTO À SECRETARIA MUNICIPAL DE SAÚDE, VISANDO COMBATE AOS FOCOS DE DENGUE NO BAIRRO DE IPANEMA. | E5: IPANEMA
A6: 5 | B6: COMLURB | C6: SOLICITA PROVIDÊNCIAS JUNTO À COMPANHIA MUNICIPAL DE LIMPEZA URBANA - COMLURB, VISANDO LIMPEZA DA PRAÇA NOSSA SENHORA DA PAZ, NO BAIRRO DE IPANEMA. | E6: IPANEMA
A7: 6 | B7: COMLURB | C7: SOLICITA PROVIDÊNCIAS JUNTO À COMPANHIA MUNICIPAL DE LIMPEZA URBANA - COMLURB, VISANDO RETIRADA DE LIXO NA COMUNIDADE SANTA MARTA, NAS PROXIMIDADES DA RUA OSWALDO SEABRA, 961. | E7: SANTA MARTA
A8: 7 | B8: SMTR | C8: SOLICITA PROVIDÊNCIAS JUNTO À SECRETARIA MUNICPAL DE TRANSPORTES E AO PROCON CARIOCA VISANDO AUMENTO DA FROTA 538/539 LEME-ROCINHA | E8: LEME
A9: 8 | B9: COMLURB | C9: SOLICITA PROVIDÊNCIAS JUNTO À COMPANHIA MUNICIPAL DE LIMPEZA URBANA - COMLURB, VISANDO VARRIÇÃO DE LOGRADOURO - RUA MAJOR RUBENS VAZ, NO BAIRRO DA GÁVEA | E9: GÁVEA
A10: 9 | B10: SECONSERVA | C10: SOLICITA PROVIDÊNCIAS JUNTO À SECRETARIA MUNICIPAL DE CONSERVAÇÃO - SECONSERVA, VISANDO TAPA BURACO NA RUA JOÃO AFONSO N°108, NO BAIRRO DO HUMAÍTA | E10: HUMAITÁ
A11: 10 | B11: COMLURB | C11: SOLICITA PROVIDÊNCIAS JUNTO À COMPANHIA MUNICIPAL DE LIMPEZA URBANA - COMLURB, VISANDO PODA NA RUA GENERAL URQUIZA COM JOÃO DE BARROS, NO BAIRRO DO LEBLON | E11: LEBLON
A12: 11 | B12: COMLURB | C12: SOLICITA PROVIDÊNCIAS JUNTO À COMPANHIA MUNICIPAL DE LIMPEZA URBANA - COMLURB, VISANDO PODA NA RUA GENERAL SEVERIANO, Nº 170, NO BAIRRO DE BOTAFOGO | E12: BOTAFOGO
A13: 12 | B13: COMLURB | C13: SOLICITA PROVIDÊNCIAS JUNTO À COMPANHIA MUNICIPAL DE LIMPEZA URBANA - COMLURB, VISANDO SERVIÇO DE ROÇADA NA RUA JOÃO AFONSO, Nº 86 -, NO BAIRRO DO HUMAITÁ | E13: HUMAITÁ
... A70: 69 | B70: COMLURB | C70: SOLICITA PROVIDÊNCIAS JUNTO À COMPANHIA MUNICIPAL DE LIMPEZA URBANA – COMLURB E À SECRETARIA MUNICIPAL DE MEIO AMBIENTE E CLIMA – SMAC, PARA VIABILIZAR A MANUTENÇÃO DE ÁREA VERDE NA RUA TONELERO, Nº 311, NO BAIRRO DE COPACABANA | E70: COPACABANA
A71: 70 | C71: SOLICITA PROVIDÊNCIAS JUNTO À SECRETARIA MUNICIPAL DO ENVELHECIMENTO SAUDÁVEL E QUALIDADE DE VIDA – SEMESQV, VISANDO A INSTALAÇÃO DE ACADEMIA AO AR LIVRE NA ESTRADA DA GÁVEA, Nº 232, NA PRACINHA DA ROCINHA | E71: ROCINHA
A72: 71 | B72: CET-RIO | C72: SOLICITA PROVIDÊNCIAS JUNTO À COMPANHIA DE ENGENHARIA DE TRÁFEGO DO RIO DE JANEIRO – CET-RIO, VISANDO ESTUDO DE VIABILIDADE PARA INSTALAÇÃO DE QUEBRA-MOLAS NA ESTRADA DA GÁVEA | E72: ROCINHA
A73: 72 | B73: RIOLUZ | C73: SOLICITA PROVIDÊNCIAS JUNTO À COMPANHIA MUNICIPAL DE ENERGIA E ILUMINAÇÃO – RIOLUZ, VISANDO MELHORIA NA ILUMINAÇÃO DA CICLOVIA ENTRE BOTAFOGO E COPACABANA | E73: BOTAFOGO
A74: 73 | B74: RIOLUZ | C74: SOLICITA PROVIDÊNCIAS JUNTO À COMPANHIA MUNICIPAL DE ENERGIA E ILUMINAÇÃO – RIOLUZ, VISANDO A RETIRADA DE POSTES OCIOSOS NA RUA MONTE ALEGRE, Nº 348, NO BAIRRO DE SANTA TERESA | E74: SANTA TERESA
A75: 74 | B75: COMLURB | C75: SOLICITA PROVIDÊNCIAS JUNTO À COMPANHIA MUNICIPAL DE LIMPEZA URBANA – COMLURB, PARA O ENVIO DO LAUDO REFERENTE À PODA REALIZADA NA CASA DE SAÚDE SÃO SEBASTIÃO, LOCALIZADA NA RUA BENTO LISBOA, Nº 160, NO BAIRRO DO CATETE | E75: CATETE
A76: 75 | B76: COMLURB | C76: SOLICITA PROVIDÊNCIAS JUNTO À COMPANHIA MUNICIPAL DE LIMPEZA URBANA – COMLURB, PARA VIABILIZAR PODA NA PRAÇA MILTON CAMPOS, Nº 1, NO BAIRRO DO LEBLON | E76: LEBLON
A77: 76 | B77: SECONSERVA | C77: SOLICITA PROVIDÊNCIAS JUNTO À SECRETARIA MUNICIPAL DE CONSERVAÇÃO E SERVIÇOS PÚBLICOS – SECONSERVA, REFERENTE ÀS AÇÕES NA RUA VOLUNTÁRIOS DA PÁTRIA, Nº 283, NO BAIRRO DE BOTAFOGO | E77: BOTAFOGO
A78: 77 | B78: SECONSERVA | C78: SOLICITA PROVIDÊNCIAS JUNTO À SECRETARIA MUNICIPAL DE CONSERVAÇÃO E SERVIÇOS PÚBLICOS – SECONSERVA, REFERENTE ÀS AÇÕES NA RUA SÃO CLEMENTE, Nº 226, NO BAIRRO DE BOTAFOGO | E78: BOTAFOGO
A79: 78 | B79: RIOLUZ | C79: SOLICITA PROVIDÊNCIAS JUNTO À COMPANHIA MUNICIPAL DE ENERGIA E ILUMINAÇÃO – RIOLUZ, VISANDO RESTABELECIMENTO DA ILUMINAÇÃO NA PRAÇA MILTON CAMPOS, NO BAIRRO DO LEBLON | E79: LEBLON
A80: 79 | B80: SECONSERVA | C80: SOLICITA PROVIDÊNCIAS JUNTO À SECRETARIA MUNICIPAL DE CONSERVAÇÃO E SERVIÇOS PÚBLICOS – SECONSERVA, REFERENTE ÀS AÇÕES NA RUA PEDRO AMÉRICO, Nº 90, NO BAIRRO DO CATETE | E80: CATETE
A81: 80 | C81: SOLICITA PROVIDÊNCIAS JUNTO À SUPERINTENDÊNCIA EXECUTIVA DE PATRIMÔNIO IMOBILIÁRIO – F/SUBEX/SUPPA, REFERENTE À TROCA DE PLACAS DE RUA NA PRAÇA CORUMBÁ, NO BAIRRO DE BOTAFOGO | E81: BOTAFOGO
A82: 81 | B82: CET-RIO | C82: SOLICITA PROVIDÊNCIAS JUNTO À COMPANHIA DE ENGENHARIA DE TRÁFEGO DO RIO DE JANEIRO – CET-RIO, VISANDO PINTURA DAS FAIXAS DE SINALIZAÇÃO NA RUA PACHECO LEÃO, Nº 1418, NO BAIRRO DO JARDIM BOTÂNICO | E82: JARDIM BOTÂNICO
A83: 82 | B83: COMLURB | C83: SOLICITA PROVIDÊNCIAS JUNTO À COMPANHIA MUNICIPAL DE LIMPEZA URBANA – COMLURB E À SECRETARIA MUNICIPAL DE CONSERVAÇÃO E SERVIÇOS PÚBLICOS – SECONSERVA, PARA VIABILIZAR A MANUTENÇÃO DOS BRINQUEDOS, MOBILIÁRIOS E GRADIL DA PRAÇA NOSSA SENHORA DA PAZ, NO BAIRRO DE IPANEMA | E83: IPANEMA
A84: 83 | B84: CET-RIO | C84: SOLICITA PROVIDÊNCIAS JUNTO À COMPANHIA DE ENGENHARIA DE TRÁFEGO DO RIO DE JANEIRO – CET-RIO E À SECRETARIA MUNICIPAL DE ORDEM PÚBLICA – SEOP, VISANDO A REPOSIÇÃO DE PLACAS DE SINALIZAÇÃO E FISCALIZAÇÃO DE ESTACIONAMENTO IRREGULAR NA RUA BARÃO DA TORRE, NO BAIRRO DE IPANEMA | E84: IPANEMA
A85: 84 | B85: SMAS | C85: SOLICITA PROVIDÊNCIAS JUNTO À SECRETARIA MUNICIPAL DE ASSISTÊNCIA SOCIAL – SMAS, REFERENTE ÀS AÇÕES NO PARQUE ESTADUAL DA CHACRINHA, LOCALIZADO NA RUA GUIMARÃES NATAL, S/N, NO BAIRRO DE COPACABANA | E85: COPACABANA
A86: 85 | B86: COMLURB | C86: SOLICITA PROVIDÊNCIAS JUNTO À COMPANHIA MUNICIPAL DE LIMPEZA URBANA – COMLURB E À SECRETARIA MUNICIPAL DE ORDEM PÚBLICA – SEOP, PARA VIABILIZAR LIMPEZA E MANUTENÇÃO DO PARQUE ESTADUAL DA CHACRINHA, NO BAIRRO DE COPACABANA | E86: COPACABANA
A87: 86 | B87: SMAS | C87: SOLICITA PROVIDÊNCIAS JUNTO À SECRETARIA MUNICIPAL DE ASSISTÊNCIA SOCIAL – SMAS, REFERENTE ÀS AÇÕES NA PRAÇA DO LARGO DO MACHADO, Nº 1, NO BAIRRO DO CATETE | E87: CATETE
A88: 87 | B88: COMLURB | C88: SOLICITA PROVIDÊNCIAS JUNTO À SECRETARIA MUNICIPAL DE CONSERVAÇÃO E SERVIÇOS PÚBLICOS – SECONSERVA E À COMPANHIA MUNICIPAL DE LIMPEZA URBANA – COMLURB, PARA VIABILIZAR MANUTENÇÃO NO PARQUE GAROTA DE IPANEMA, NO BAIRRO DE IPANEMA | E88: IPANEMA
A89: 88 | B89: SEOP | C89: SOLICITA PROVIDÊNCIAS JUNTO À SECRETARIA MUNICIPAL DE ORDEM PÚBLICA – SEOP E À GUARDA MUNICIPAL, VISANDO INTENSIFICAR AÇÕES DE ORDENAMENTO NA RUA HUMBERTO DE CAMPOS, NO BAIRRO DO LEBLON | E89: LEBLON
A90: 89 | B90: SEOP | C90: SOLICITA PROVIDÊNCIAS JUNTO À SECRETARIA MUNICIPAL DE ORDEM PÚBLICA – SEOP E À GUARDA MUNICIPAL, VISANDO INTENSIFICAR A FISCALIZAÇÃO NA RUA SIQUEIRA CAMPOS, Nº 20, NO BAIRRO DE COPACABANA | E90: COPACABANA
A91: 90 | B91: SEOP | C91: SOLICITA PROVIDÊNCIAS JUNTO À SECRETARIA MUNICIPAL DE ORDEM PÚBLICA – SEOP E À GUARDA MUNICIPAL, VISANDO FISCALIZAÇÃO DE ESTACIONAMENTO IRREGULAR NA CALÇADA DA PRAÇA GENERAL OSÓRIO, NO BAIRRO DE IPANEMA | E91: IPANEMA
A92: 91 | B92: SECONSERVA | C92: SOLICITA PROVIDÊNCIAS JUNTO À SECRETARIA MUNICIPAL DE CONSERVAÇÃO E SERVIÇOS PÚBLICOS – SECONSERVA, REFERENTE ÀS AÇÕES NA AVENIDA PADRE LEONEL FRANCA, Nº 261, NO BAIRRO DA GÁVEA | E92: GÁVEA
A93: 92 | B93: COMLURB | C93: SOLICITA PROVIDÊNCIAS JUNTO À COMPANHIA MUNICIPAL DE LIMPEZA URBANA – COMLURB, PARA VIABILIZAR PODA NA AVENIDA PADRE LEONEL FRANCA, Nº 261, NO BAIRRO DA GÁVEA | E93: GÁVEA
... A148: 147 | B148: SECONSERVA | C148: SOLICITA PROVIDÊNCIAS JUNTO À EMPRESA MUNICIPAL DE ILUMINAÇÃO URBANA – RIOLUZ E À SECRETARIA MUNICIPAL DE CONSERVAÇÃO E SERVIÇOS PÚBLICOS – SECONSERVA, REFERENTE A POSTES DANIFICADOS E EMPECILHOS À ACESSIBILIDADE NA RUA SÃO LUIZ GONZAGA, NO BAIRRO DE BENFICA | E148: BENFICA
A149: 148 | B149: SECONSERVA | C149: SOLICITA PROVIDÊNCIAS JUNTO À SECRETARIA MUNICIPAL DE CONSERVAÇÃO E SERVIÇOS PÚBLICOS – SECONSERVA, REFERENTE A AÇÕES DE CONSERVAÇÃO NA RUA SÃO LUIZ GONZAGA, NO BAIRRO DE SÃO CRISTÓVÃO
A150: 149 | B150: SEOP | C150: SOLICITA PROVIDÊNCIAS JUNTO À SECRETARIA MUNICIPAL DE ORDEM PÚBLICA – SEOP, REFERENTE À FISCALIZAÇÃO DE OBSTRUÇÃO DE ÁREA PÚBLICA NA RUA SENADOR SIMONSEN, NO BAIRRO DO JARDIM BOTÂNICO | E150: JARDIM BOTÂNICO
...

Sheet Assessoria de Imprensa
A1: TIPO | B1: DATA | C1: MÊS | D1: ASSUNTO | E1: TITULO | F1: VEÍCULO | G1: JORNALISTA | H1: LINK | I1: ASPAS | J1: CITAÇÃO
A2: RELEASE | B2: 45681 | C2: =(IF(ISBLANK(B2),"",TEXT(DATE(MID(B2,7,4), MID(B2,4,2), MID(B2,1,2)), "mm/yyyy"))) -> 01/2025 | D2: Combate ao Antissemitismo | E2: O custo do antissemitismo para o turismo brasileiro | F2: VEJA RIO | G2: LU LACERDA | H2: https://vejario.abril.com.br/coluna/lu-lacerda/o-custo-do-antissemitismo-para-o-turismo-brasileiro/ | I2: Segundo dados do gabinete, mais ou menos 11,9 mil israelenses judeus visitaram o Brasil no ano passado (dados da Embratur), com uma movimentação de R$ 54,5 milhões (dados do Banco Central). “Um país plural e diverso não pode ter uma perda significativa no turismo, setor que somos referência, por atitudes antissemitas”, diz o vereador.
A3: RELEASE | B3: 45683 | C3: =(IF(ISBLANK(B3),"",TEXT(DATE(MID(B3,7,4), MID(B3,4,2), MID(B3,1,2)), "mm/yyyy"))) -> 01/2025 | D3: Combate ao Antissemitismo | E3: Sobrevivente do holocausto: é preciso denunciar apologias ao nazismo | F3: AGENCIA BRASIL | G3: Mariana Tokarnia | H3: https://agenciabrasil.ebc.com.br/geral/noticia/2025-01/sobrevivente-do-holocausto-e-preciso-denunciar-apologias-ao-nazismo | J3: O evento no Palácio da Cidade, sob o tema 80 anos depois: Memória, Resistência e Esperança, foi uma ação colaborativa entre o vereador Flávio Valle e a Federação Israelita do Estado do Rio de Janeiro (FIERJ) e com apoios da Prefeitura, e da Confederação Israelita do Brasil (Conib). A cerimônia reuniu autoridades, sobreviventes do Holocausto e seus descendentes, políticos e autoridades eclesiais. | W3: MÊS | X3: Causa Animal | Y3: Combate ao Antissemitismo | Z3: Conservação | AA3: Economia | AB3: Esporte e Lazer | AC3: Gabinete | AD3: Meio Ambiente | AE3: Ordenamento | AF3: Saúde | AG3: Segurança | AH3: Turismo | AK3: MÊS | AL3: NOTA | AM3: COLUNA | AN3: ENTREVISTA | AO3: MATÉRIA | AP3: ARTIGO | AQ3: NOTÍCIA | AR3: REDAÇÃO | AS3: REPORTAGEM | AT3: RELEASE
A4: RELEASE | B4: 45683 | C4: =(IF(ISBLANK(B4),"",TEXT(DATE(MID(B4,7,4), MID(B4,4,2), MID(B4,1,2)), "mm/yyyy"))) -> 01/2025 | D4: Combate ao Antissemitismo | E4: Comunidade judaica homenageia vítimas do Holocausto em evento na Zona Sul | F4: O DIA | G4: REDAÇÃO | H4: https://odia.ig.com.br/rio-de-janeiro/2025/01/6992495-comunidade-judaica-homenageia-vitimas-do-holocausto-em-evento-na-zona-sul.html | I4: O vereador Flávio Valle, que é judeu, destacou a importância do enfrentamento ao preconceito contra judeus: "O combate ao antissemitismo não é apenas uma questão de memória histórica, mas uma necessidade urgente da atualidade". | W4: janeiro/2025 | Y4: 9 | AK4: janeiro/2025 | AL4: Agendas! | AP4: 1 | AT4: 7
A5: RELEASE | B5: 45683 | C5: =(IF(ISBLANK(B5),"",TEXT(DATE(MID(B5,7,4), MID(B5,4,2), MID(B5,1,2)), "mm/yyyy"))) -> 01/2025 | D5: Combate ao Antissemitismo | E5: Comunidade judaica do Rio presta homenagem às vítimas do Holocausto em evento no Palácio da Cidade | F5: DIÁRIO DO RIO | G5: QUINTINO GOMES FREIRE | H5: https://diariodorio.com/comunidade-judaica-do-rio-presta-homenagem-as-vitimas-do-holocausto-em-evento-no-palacio-da-cidade/ | I5: O vereador Flávio Valle reforçou a necessidade de combater o antissemitismo de forma contínua. “O combate ao antissemitismo não é apenas uma questão de memória histórica, mas uma necessidade urgente da atualidade. No parlamento, seguirei promovendo iniciativas legislativas que garantam a segurança da comunidade judaica, a educação sobre o Holocausto e a defesa dos direitos humanos”, afirmou. | J5: O evento, realizado sob o tema “80 anos depois: Memória, Resistência e Esperança”, foi fruto de uma parceria entre o vereador Flávio Valle, a Federação Israelita do Estado do Rio de Janeiro (FIERJ), a Prefeitura do Rio e a Confederação Israelita do Brasil (Conib). Amanhã, 27 de janeiro, o mundo celebra o Dia Internacional em Memória das Vítimas do Holocausto, instituído pela ONU em 2005, através da Resolução 60/7. | W5: fevereiro/2025 | Y5: 5 | AC5: 4 | AD5: 2 | AE5: 2 | AG5: 2 | AH5: 3 | AK5: fevereiro/2025 | AL5: 6 | AP5: 1 | AT5: 11
A6: ARTIGO | B6: 45684 | C6: =(IF(ISBLANK(B6),"",TEXT(DATE(MID(B6,7,4), MID(B6,4,2), MID(B6,1,2)), "mm/yyyy"))) -> 01/2025 | D6: Combate ao Antissemitismo | E6: O Holocausto foi o ápice do antissemitismo, mas não o seu fim | F6: DIÁRIO DO RIO | G6: FLÁVIO VALLE | H6: https://diariodorio.com/o-holocausto-foi-o-apice-do-antissemitismo-mas-nao-seu-fim/ | W6: março/2025 | Y6: 1 | AA6: 1 | AC6: 5 | AH6: 18 | AK6: março/2025 | AL6: 15 | AM6: 1 | AO6: 1 | AP6: 1 | AS6: 1 | AT6: 6
A7: RELEASE | B7: 45684 | C7: =(IF(ISBLANK(B7),"",TEXT(DATE(MID(B7,7,4), MID(B7,4,2), MID(B7,1,2)), "mm/yyyy"))) -> 01/2025 | D7: Combate ao Antissemitismo | E7: Tem que combater’, diz sobrevivente do Holocausto sobre apologia ao nazismo | F7: AMAZONAS ATUAL | G7: REDAÇÃO | H7: https://amazonasatual.com.br/tem-que-combater-diz-sobrevivente-do-holocausto-sobre-apologia-ao-nazismo/ | J7: O evento no Palácio da Cidade, sob o tema 80 anos depois: Memória, Resistência e Esperança, foi uma ação colaborativa entre o vereador Flávio Valle e a Federação Israelita do Estado do Rio de Janeiro (FIERJ) e com apoios da Prefeitura, e da Confederação Israelita do Brasil (Conib). A cerimônia reuniu autoridades, sobreviventes do Holocausto e seus descendentes, políticos e autoridades eclesiais. | W7: abril/2025 | X7: 1 | Y7: 1 | AA7: 1 | AB7: 1 | AC7: 1 | AD7: 3 | AE7: 3 | AH7: 1 | AK7: abril/2025 | AL7: 2 | AT7: 10
A8: NOTA | B8: 45684 | C8: =(IF(ISBLANK(B8),"",TEXT(DATE(MID(B8,7,4), MID(B8,4,2), MID(B8,1,2)), "mm/yyyy"))) -> 01/2025 | D8: Combate ao Antissemitismo | E8: É preciso denunciar apologias ao nazismo, diz sobrevivente do Holocausto em cerimônia no Rio | F8: R7 | H8: https://noticias.r7.com/cidades/e-preciso-denunciar-apologias-ao-nazismo-diz-sobrevivente-do-holocausto-em-cerimonia-no-rio-27012025/ | J8: O evento no Palácio da Cidade, sob o tema ’80 anos depois: Memória, Resistência e Esperança', foi uma ação colaborativa entre o vereador Flávio Valle e a FIERJ (Federação Israelita do Estado do Rio de Janeiro) e com apoios da Prefeitura, e da Conib (Confederação Israelita do Brasil). | W8: maio/2025 | Y8: 9 | Z8: 1 | AC8: 11 | AD8: 1 | AE8: 43 | AH8: 4 | AK8: maio/2025 | AL8: 40 | AM8: 2 | AN8: 1 | AQ8: 1 | AR8: 1 | AT8: 24
A9: RELEASE | B9: 45684 | C9: =(IF(ISBLANK(B9),"",TEXT(DATE(MID(B9,7,4), MID(B9,4,2), MID(B9,1,2)), "mm/yyyy"))) -> 01/2025 | D9: Combate ao Antissemitismo | E9: Comunidade judaica do RJ presta homenagem às vítimas do Holocausto em evento no Palácio da Cidade | F9: Conib | H9: https://conib.org.br/noticias-conib/39403-comunidade-judaica-do-rj-presta-homenagem-as-vitimas-do-holocausto-em-evento-no-palacio-da-cidade.html | I9: "O combate ao antissemitismo não é apenas uma questão de memória histórica, mas uma necessidade urgente da atualidade. Como vereador do Rio de Janeiro levo essa bandeira para dentro do parlamento e continuarei trabalhando para que a nossa cidade se torne um modelo no combate ao antissemitismo, promovendo iniciativas legislativas que garantam a segurança da comunidade judaica, a educação sobre o Holocausto e a defesa dos direitos humanos", disse o vereador Flávio Valle. | J9: Flávio Valle também anunciou o estudo realizado por seu gabinete que aponta o custo do antissemitismo para o turismo brasileiro. Segundo dados levantados pelo gabinete do vereador, cerca de 11,9 mil israelenses judeus visitaram o Brasil no ano passado (dados da Embratur), com um impacto na economia brasileira de aproximadamente R$54,5 milhões (dados do Banco Central). | W9: junho/2025 | Y9: 30 | Z9: 2 | AC9: 1 | AE9: 5 | AF9: 1 | AH9: 3 | AK9: junho/2025 | AL9: 28 | AM9: 4 | AT9: 10
A10: RELEASE | B10: 45687 | C10: =(IF(ISBLANK(B10),"",TEXT(DATE(MID(B10,7,4), MID(B10,4,2), MID(B10,1,2)), "mm/yyyy"))) -> 01/2025 | D10: Combate ao Antissemitismo | E10: Câmara do rio remove pichação com suástica nazista em um de seus banheiros | F10: O GLOBO | G10: JOÃO PAULO SACCONI | H10: https://oglobo.globo.com/blogs/lauro-jardim/post/2025/01/camara-do-rio-remove-pichacao-com-suastica-nazista-em-um-de-seus-banheiros.ghtml
A11: ARTIGO | B11: 45684 | C11: =(IF(ISBLANK(B11),"",TEXT(DATE(MID(B11,7,4), MID(B11,4,2), MID(B11,1,2)), "mm/yyyy"))) -> 01/2025 | D11: Combate ao Antissemitismo | E11: O Holocausto foi o ápice do antissemitismo, mas não o seu fim | F11: DIARIO DO RIO | G11: FLAVIO VALLE | H11: https://diariodorio.com/o-holocausto-foi-o-apice-do-antissemitismo-mas-nao-seu-fim/
A12: ARTIGO | B12: 45691 | C12: =(IF(ISBLANK(B12),"",TEXT(DATE(MID(B12,7,4), MID(B12,4,2), MID(B12,1,2)), "mm/yyyy"))) -> 02/2025 | D12: Turismo | E12: O impulso para alavancar tecnologia, sustentabilidade e finanças no Rio de Janeiro | F12: DIÁRIO DO RIO | G12: FLAVIO VALLE | H12: https://diariodorio.com/o-impulso-para-alavancar-tecnologia-sustentabilidade-e-financas-no-rio-de-janeiro-flaviovalle/
A13: NOTA | B13: 45693 | C13: =(IF(ISBLANK(B13),"",TEXT(DATE(MID(B13,7,4), MID(B13,4,2), MID(B13,1,2)), "mm/yyyy"))) -> 02/2025 | D13: Mandato | E13: Vindo de bons resultados, Câmara terá pelada situação x oposição | F13: TEMPO REAL | G13: VITOR D'AVILA | H13: https://temporealrj.com/vindo-de-bons-resultados-camara-tera-pelada-situacao-x-oposicao/ | J13: Nesta quinta-feira (6), acontecerá a pelada situação x oposição. Do lado dos mais chegados ao prefeito Eduardo Paes (PSD), estará o vereador Flávio Valle capitaneando o time. Já o combinado adversário será encabeçado por Pedro Duarte (Novo). Só não vale ir na canela!
A14: NOTA | B14: 45695 | C14: =(IF(ISBLANK(B14),"",TEXT(DATE(MID(B14,7,4), MID(B14,4,2), MID(B14,1,2)), "mm/yyyy"))) -> 02/2025 | D14: Mandato | E14: Pelada entre situação e oposição da Câmara de Vereadores termina empatada | F14: TEMPO REAL | G14: VITOR D'AVILA | H14: https://temporealrj.com/pelada-entre-situacao-e-oposicao-da-camara-de-vereadores-termina-empatada/ | J14: Ao menos no futebol, situação e oposição da Câmara de Vereadores do Rio estão em pé de igualdade. O jogo de futebol entre os gabinetes dos vereadores Pedro Duarte (Novo) e Flávio Valle (PSD), na noite de quinta-feira (6), foi bastante combativo, como se fala no jargão político, mas terminou com placar empatado.
A15: RELEASE | B15: 45698 | C15: =(IF(ISBLANK(B15),"",TEXT(DATE(MID(B15,7,4), MID(B15,4,2), MID(B15,1,2)), "mm/yyyy"))) -> 02/2025 | D15: Ordenamento | E15: Vereador Flávio Valle participa de ação educativa sobre uso das vias fechadas na orla da Zona Sul | F15: DIÁRIO DO RIO | G15: QUINTINO GOMES FREIRE | H15: https://diariodorio.com/vereador-flavio-valle-participa-de-acao-educativa-sobre-uso-das-vias-fechadas-na-orla-da-zona-sul/ | I15: “Atualmente, uma simples caminhada pela orla nas áreas fechadas para lazer aos domingos e feriados pode representar um risco considerável de sofrer um acidente. Não são poucos os condutores de motos e bicicletas elétricas que circulam em alta velocidade nessas vias, causando transtornos para os pedestres, principalmente para crianças e idosos. Esperamos que essas ações colaborem com a conscientização de todos sobre a importância de se respeitar as regras estabelecidas para o bom convívio entre todos”, destacou Valle. | J15: Na manhã deste domingo (9), o vereador Flávio Valle participou de uma ação educativa promovida pela Prefeitura do Rio, com o objetivo de conscientizar usuários sobre a proibição da circulação de bicicletas e bikes elétricas nas vias fechadas para lazer aos domingos e feriados.
A16: RELEASE | B16: 45705 | C16: =(IF(ISBLANK(B16),"",TEXT(DATE(MID(B16,7,4), MID(B16,4,2), MID(B16,1,2)), "mm/yyyy"))) -> 02/2025 | D16: Meio Ambiente | E16: Tem até gavião carijó aparecendo na naturalizada Lagoa Rodrigo de Freitas | F16: O GLOBO | G16: NELSON LIMA NETO | H16: https://oglobo.globo.com/blogs/ancelmo-gois/post/2025/02/tem-ate-gaviao-carijo-aparecendo-na-naturalizada-lagoa-rodrigo-de-freitas.ghtml
A17: RELEASE | B17: 45706 | C17: =(IF(ISBLANK(B17),"",TEXT(DATE(MID(B17,7,4), MID(B17,4,2), MID(B17,1,2)), "mm/yyyy"))) -> 02/2025 | D17: Combate ao Antissemitismo | E17: Vereador apresenta três propostas para combater o antissemitismo no Rio | F17: DIÁRIO DO RIO | G17: QUINTINO GOMES FREIRE | H17: https://diariodorio.com/vereador-apresenta-tres-propostas-para-combater-o-antissemitismo-no-rio/ | I17: “Infelizmente, o ódio contra os judeus ainda persiste, algumas vezes de forma explícita e em outras, disfarçado sob diferentes pretextos. O Rio é uma cidade turística, reconhecida por sua diversidade e pluralidade, e não podemos normalizar o preconceito, a hostilidade ou a discriminação. Conto com meus colegas vereadores para institucionalizar essa pauta na Câmara Municipal e servir de exemplo para outras cidades”, afirmou o vereador | J17: O vereador Flávio Valle (PSD) segue empenhado no combate ao antissemitismo na cidade do Rio de Janeiro. Após garantir que a Prefeitura do Rio fosse a primeira do Brasil a adotar a definição de antissemitismo estabelecida pela Aliança Internacional para a Memória do Holocausto (IHRA), em novembro de 2023, o parlamentar agora leva a pauta para a Câmara Municipal.
A18: RELEASE | B18: 45707 | C18: =(IF(ISBLANK(B18),"",TEXT(DATE(MID(B18,7,4), MID(B18,4,2), MID(B18,1,2)), "mm/yyyy"))) -> 02/2025 | D18: Segurança | E18: Lei anti-Oruam: 'Menores são vítimas e até algozes do crime', diz vereador do Rio | F18: REVISTA OESTE | G18: EUGENIO GOUSSINSKY | H18: https://revistaoeste.com/brasil/lei-anti-oruammenores-sao-vitimas-e-ate-algozes-do-crime-diz-vereador-do-rio-de-janeiro/ | I18: "O texto tem que estar muito bem escrito para não abrir brechas que o enfraqueçam, a música é um instrumento de cultura para criticar certos comportamentos da sociedade, há uma linha tênue entre o que é crítica e o que é apologia", ', alerta Valle, que se coloca como favorável ao projeto. | J18: Na tramitação do projeto, antes de ser votado, alguns vereadores, como Flávio Valle (PSD), buscarão definir o limiar entre liberdade de expressão e apologia do crime.
A19: RELEASE | B19: 45707 | C19: =(IF(ISBLANK(B19),"",TEXT(DATE(MID(B19,7,4), MID(B19,4,2), MID(B19,1,2)), "mm/yyyy"))) -> 02/2025 | D19: Turismo | E19: Visit Rio celebra nomeação de Flávio Valle (PSD) como presidente da Comissão de Turismo da Câmara Municipal do RJ | F19: MERCADO E EVENTOS | G19: JANAÍNA BRITO | H19: https://www.mercadoeeventos.com.br/noticias/politica/visit-rio-celebra-nomeacao-de-flavio-valle-psd-como-presidente-da-comissao-de-turismo-da-camara-municipal-do-rj/ | I19: "O turismo é um dos principais motores da economia carioca, gerando empregos, impulsionando o desenvolvimento regional e promovendo a preservação cultural. O Visit Rio acredita que a renovação e a presença de jovens lideranças contribuem para a pluralidade de ideias. Reforçamos nosso compromisso com o fortalecimento do setor e nos colocamos à disposição para contribuir com sua atuação em prol do turismo na cidade", afirmou a entidade. | J19: O Visit Rio Convention Bureau celebrou, em nota enviada à imprensa, a nomeação do vereador Flávio Valle (PSD) como presidente da Comissão de Turismo da Câmara Municipal do Rio de Janeiro. Flávio, que foi subprefeito da Zona Sul, é reconhecido como uma promissora liderança do Rio e está apto a impulsionar políticas que beneficiem a cidade e o turismo.
A20: RELEASE | B20: 45708 | C20: =(IF(ISBLANK(B20),"",TEXT(DATE(MID(B20,7,4), MID(B20,4,2), MID(B20,1,2)), "mm/yyyy"))) -> 02/2025 | D20: Combate ao Antissemitismo | E20: Câmara do Rio terá Frente Parlamentar de Combate ao Antissemitismo | F20: CÂMARA MUNICIPAL DOS VEREADORES | H20: https://www.camara.rio/comunicacao/noticias/2505-camara-do-rio-tera-frente-parlamentar-de-combate-ao-antissemitismo | I20: “Infelizmente o ódio contra judeus ainda persiste, algumas vezes de forma explícita, e em outras disfarçado sob diferentes pretextos para propagar sua disseminação. O Rio é uma cidade turística e reconhecida por sua diversidade e pluralidade, não podemos normalizar preconceito, hostilidade ou discriminação”, ressaltou o vereador, que é o único judeu no parlamento carioca. | J20: Valle apresentou outras duas propostas para fortalecimento do combate ao antissemitismo no Rio de Janeiro. Uma torna lei a adoção de definição de antissemitismo da IHRA (Aliança Internacional para a Memória do Holocausto) e outra inclui no calendário oficial da cidade o “Dia de Combate ao Antissemitismo”, a ser celebrado em 7 de outubro, data do ataque terrorista do Hamas a Israel.
A21: RELEASE | B21: 45708 | C21: =(IF(ISBLANK(B21),"",TEXT(DATE(MID(B21,7,4), MID(B21,4,2), MID(B21,1,2)), "mm/yyyy"))) -> 02/2025 | D21: Combate ao Antissemitismo | E21: Com aumento de casos, Câmara do Rio cria Frente Parlamentar contra antissemitismo | F21: AGENDA DO PODER | G21: CÁRTER ANDERSON | H21: https://agendadopoder.com.br/com-aumento-de-casos-camara-do-rio-cria-frente-parlamentar-contra-antissemitismo/#google_vignette | I21: “Infelizmente, o ódio contra judeus ainda persiste, algumas vezes de forma explícita, e em outras disfarçado sob diferentes pretextos para propagar sua disseminação. O Rio é uma cidade turística e reconhecida por sua diversidade e pluralidade, não podemos normalizar preconceito, hostilidade ou discriminação”, destacou Valle, que é o único vereador judeu da Câmara carioca. | J21: A iniciativa, publicada no Diário Oficial da Casa nesta quinta-feira (20), foi proposta pelo vereador Flávio Valle (PSD), em parceria com Marcos Dias (Podemos) e Pedro Duarte (Novo). O requerimento contou com o apoio de 25 parlamentares, o que garantiu sua aprovação automática.
A22: NOTA | B22: 45708 | C22: =(IF(ISBLANK(B22),"",TEXT(DATE(MID(B22,7,4), MID(B22,4,2), MID(B22,1,2)), "mm/yyyy"))) -> 02/2025 | D22: Combate ao Antissemitismo | E22: Câmara do Rio cria Frente Parlamentar de Combate ao Antissemitismo | F22: VEJA RIO | G22: LU LACERDA | H22: https://vejario.abril.com.br/coluna/lu-lacerda/camara-do-rio-cria-frente-parlamentar-de-combate-ao-antissemitismo/ | I22: “Infelizmente o ódio contra judeus ainda persiste, algumas vezes de forma explícita, e em outras disfarçado sob diferentes pretextos. O Rio é uma cidade turística e reconhecida por sua diversidade e ... Leia mais em: https://vejario.abril.com.br/coluna/lu-lacerda/camara-do-rio-cria-frente-parlamentar-de-combate-ao-antissemitismo/ | J22: Ação dos vereadores Flávio Valle, Marcos Dias e Pedro Duarte, com apoio de outros 25 vereadores, o que garantiu a sua criação imediata. Leia mais em: https://vejario.abril.com.br/coluna/lu-lacerda/camara-do-rio-cria-frente-parlamentar-de-combate-ao-antissemitismo/
A23: NOTA | B23: 45711 | C23: =(IF(ISBLANK(B23),"",TEXT(DATE(MID(B23,7,4), MID(B23,4,2), MID(B23,1,2)), "mm/yyyy"))) -> 02/2025 | D23: Mandato | E23: Vereadores e influencers: Flávio Valle lidera lista de crescimento de seguidores | F23: TEMPO REAL | G23: VITOR D'AVILA | H23: https://temporealrj.com/vereadores-e-influencers-flavio-valle-lidera-lista-de-crescimento-de-seguidores/ | J23: O novato Flávio Valle (PSD) aparece no topo do ranking da estatística de crescimento da base de seguidores no Instagram, no último mês, com um aumento de 4,9% (1.572 novos seguidores). O vereador vem seguido por Gigi Castilho (Republicanos), com 4,5% (740), e Wagner Tavares (PSB), com 4,2% (178).
A24: RELEASE | B24: 45712 | C24: =(IF(ISBLANK(B24),"",TEXT(DATE(MID(B24,7,4), MID(B24,4,2), MID(B24,1,2)), "mm/yyyy"))) -> 02/2025 | D24: Mandato | E24: Vereadores ampliam alcance digital: Flávio Valle é destaque no Instagram | F24: DIÁRIO DO RIO | G24: QUINTINO GOMES FREIRE | H24: https://diariodorio.com/vereadores-ampliam-alcance-digital-flavio-valle-e-destaque-no-instagram/ | J24: No cenário político atual, a atuação parlamentar vai além da Câmara: conquistar espaço nas redes sociais tornou-se essencial para manter o eleitor informado. No último mês, o vereador Flávio Valle (PSD) liderou o crescimento de seguidores no Instagram, com um aumento de 4,9%, equivalente a 1.572 novos seguidores.
A25: NOTA | B25: 45712 | C25: =(IF(ISBLANK(B25),"",TEXT(DATE(MID(B25,7,4), MID(B25,4,2), MID(B25,1,2)), "mm/yyyy"))) -> 02/2025 | D25: Turismo | E25: Câmara do Rio oficializa presidentes e vices de 14 comissões permanentes | F25: TEMPO REAL | H25: https://temporealrj.com/camara-do-rio-oficializa-presidentes-e-vices-de-14-comissoes-permanentes/ | J25: Comissão Permanente de Turismo: Flávio Valle (PSD) é o presidente; Jorge Canella (União Brasil) é o vice-presidente; Rocal (PSD) é o vogal interino.
A26: RELEASE | B26: 45712 | C26: =(IF(ISBLANK(B26),"",TEXT(DATE(MID(B26,7,4), MID(B26,4,2), MID(B26,1,2)), "mm/yyyy"))) -> 02/2025 | D26: Combate ao Antissemitismo | E26: Câmara do Rio terá Frente Parlamentar de Combate ao Antissemitismo | F26: CONIB | H26: https://conib.org.br/noticias/todas-as-noticias/39495-camara-do-rio-tera-frente-parlamentar-de-combate-ao-antissemitismo.html
A27: RELEASE | B27: 45713 | C27: =(IF(ISBLANK(B27),"",TEXT(DATE(MID(B27,7,4), MID(B27,4,2), MID(B27,1,2)), "mm/yyyy"))) -> 02/2025 | D27: Meio Ambiente | E27: Programa Vaga Viva propõe jardins e bicicletários em espaços de estacionamento | F27: DIÁRIO DO RIO | G27: QUINTINO GOMES FREIRE | H27: https://diariodorio.com/programa-vaga-viva-propoe-jardins-e-bicicletarios-em-espacos-de-estacionamento/ | J27: A Câmara Municipal do Rio de Janeiro analisa o Programa Vaga Viva, proposta do vereador Flavio Valle que estabelece diretrizes para a conversão de vagas de estacionamento em áreas verdes e espaços de convivência.
A28: NOTA | B28: 45715 | C28: =(IF(ISBLANK(B28),"",TEXT(DATE(MID(B28,7,4), MID(B28,4,2), MID(B28,1,2)), "mm/yyyy"))) -> 02/2025 | D28: Ordenamento | E28: Copacabana: o que vem a ser a nova pintura na Mureta do Leme? | F28: VEJA RIO | G28: LU LACERDA | H28: https://vejario.abril.com.br/coluna/lu-lacerda/copacabana-amanhecem-com-nova-pintura-na-mureta-do-leme/ | J28: Tudo começou via secretaria de Conservação, que, com a melhor das intenções, pediu ajuda ao vereador Flávio Valle, ex-subsecretário da Zona Sul, para indicar algum artista visual. Ele citou Malu Vibe... Leia mais em: https://vejario.abril.com.br/coluna/lu-lacerda/copacabana-amanhecem-com-nova-pintura-na-mureta-do-leme/
A29: RELEASE | B29: 45714 | C29: =(IF(ISBLANK(B29),"",TEXT(DATE(MID(B29,7,4), MID(B29,4,2), MID(B29,1,2)), "mm/yyyy"))) -> 02/2025 | D29: Segurança | E29: Projeto prevê que Guardas Municipais do Rio passem por processo interno para integrar Força Municipal de Segurança | F29: CBN | G29: LEONARDO REZENDE | H29: https://cbn.globo.com/rio-de-janeiro/noticia/2025/02/26/projeto-preve-que-guardas-municipais-do-rio-passem-por-processo-interno-para-integrar-forca-municipal-de-seguranca.ghtml | I29: "Tem dois pontos. Primeiro, a gente poder premiar os guardas que entendem que a função deles, como agentes públicos, deve ser a segurança pública. Eles vão poder fazer parte desse processo seletivo. Mas, além disso, a Guarda Municipal está passando por um processo de refundação da sua instituição. A prefeitura entende que a Guarda Municipal, hoje, precisa focar em olhar mais para o cidadão, focar mais na parte da zeladoria urbana, na fiscalização das posturas", disse. | J29: Vereador da base aliada do prefeito, Flavio Valle, afirmou que o município realiza uma refundação da Guarda Municipal - voltada para o ordenamento público.
A30: RELEASE | B30: 45727 | C30: =(IF(ISBLANK(B30),"",TEXT(DATE(MID(B30,7,4), MID(B30,4,2), MID(B30,1,2)), "mm/yyyy"))) -> 03/2025 | D30: Mandato | E30: Estrelismo, carnaval e bolinho de bacalhau – Bastidores do Rio | F30: DIÁRIO DO RIO | G30: QUINTINO GOMES FREIRE | H30: https://diariodorio.com/estrelismo-carnaval-e-bolinho-de-bacalhau-bastidores-do-rio/ | J30: O vereador Júnior Flávio Valle participou do Hillel International Israel Summit, em Chicago, onde lideranças judaicas discutiram o crescimento do antissemitismo em universidades americanas e estratégias de combate à desinformação.
A31: NOTA | B31: 45728 | C31: =(IF(ISBLANK(B31),"",TEXT(DATE(MID(B31,7,4), MID(B31,4,2), MID(B31,1,2)), "mm/yyyy"))) -> 03/2025 | D31: Turismo | E31: Presidente da Comissão de Turismo propõe limites para o financiamento do Carnaval | F31: TEMPO REAL | H31: https://temporealrj.com/presidente-da-comissao-de-turismo-propoe-limites-para-o-financiamento-do-carnaval/ | I31: “Precisamos discutir certos limites no financiamento do Carnaval. Por muito tempo, a prefeitura precisou aportar recursos e ela historicamente sempre fez esse papel com muita maestria, mas hoje o Carnaval é muito mais sofisticado. A cada ano que passa, a Liga Independente (Liesa) vai ficando, de fato, mais independente. E o governo do estado, há alguns anos, começou também a colocar dinheiro”, disse. | J31: Em discurso na Câmara de Vereadores, nesta terça feira (11), Flávio Valle (PSD), presidente da Comissão de Turismo, sugeriu que sejam discutidos limites para o financiamento do carnaval. Na fala, contudo, ele ressaltou a importância da festa para a economia carioca e destacou os números da arrecadação de impostos (ISS): mais de R$ 530 milhões.
A32: ARTIGO | B32: 45733 | C32: =(IF(ISBLANK(B32),"",TEXT(DATE(MID(B32,7,4), MID(B32,4,2), MID(B32,1,2)), "mm/yyyy"))) -> 03/2025 | D32: Economia | E32: Flávio Valle: Por que a Câmara Municipal do Rio deve aprovar o empréstimo solicitado pela Prefeitura | F32: O DIA | G32: Flavio Valle | H32: https://odia.ig.com.br/opiniao/2025/03/7021183-flavio-valle-por-que-a-camara-municipal-do-rio-deve-aprovar-o-emprestimo-solicitado-pela-prefeitura.html | I32: Que venham os novos investimentos!
A33: RELEASE | B33: 45734 | C33: =(IF(ISBLANK(B33),"",TEXT(DATE(MID(B33,7,4), MID(B33,4,2), MID(B33,1,2)), "mm/yyyy"))) -> 03/2025 | D33: Combate ao Antissemitismo | E33: FIERJ promove o lançamento de 'Eternamente 7 de Outubro' e debate sobre terrorismo e antissemitismo | F33: CONIB | H33: https://conib.org.br/noticias/todas-as-noticias/39554-fierj-promove-o-lancamento-de-eternamente-7-de-outubro-e-debate-sobre-terrorismo-e-antissemitismo.html | I33: "Quando a gente conta a história, disponibiliza informação, estamos educando e com isto mitigando interpretações distorcidas e prevenindo incidentes de discriminação, como o antissemitismo. A disseminação de informações corretas e o incentivo à educação são pilares essenciais para construir uma sociedade mais consciente e inclusiva. Além disso, promover o diálogo e o entendimento entre diferentes grupos culturais e religiosos fortalece a coesão social e contribui para um futuro mais justo e harmonioso”, avaliou o vereador Flavio Valle, presidente da Frente Parlamentar de Combate ao Antissemitismo da CMRJ, após o evento. | J33: Após a exibição do documentário, aconteceu uma mesa de debate com a participação do comentarista da Jovem Pan Roberto Motta, do vereador Flávio Valle, do advogado Daniel Bialski e do diretor do filme, Ronaldo Gomlevsky, que agradeceu a oportunidade em nome do presidente da FIERJ, Bruno Feigelson. Os debatedores aprofundaram o conteúdo do documentário, suas mensagens e o contexto dos eventos retratados.
